Workbook

Sheet Assumptions
A1: Diageo plc (DEO / DGE.L) — DCF Model: Assumptions
A3: Company Data
A4: Company | B4: Diageo plc
A5: Tickers | B5: DEO (NYSE ADR) / DGE.L (LSE)
A6: Fiscal Year End | B6: 30 June
A7: Valuation Date | B7: 2 Sep 2026
A8: Reporting Currency | B8: USD | C8: Diageo reports in USD despite its primary LSE listing; model values everything in USD for consistency
A10: Market Data
A11: Ordinary Shares Outstanding (m) | B11: 2220 | C11: Source: LSE.co.uk, Aug 2026 (~2.22bn ordinary shares in issue)
A12: ADR Ratio (ordinary shares per ADR) | B12: 4 | C12: Standard DEO ADR ratio
A13: DEO Share Price, USD (ADR) | B13: 90.06 | C13: Source: CNN Markets, close 27 Aug 2026 — refresh via fetch_diageo_data.py for a live price
A14: Implied Ordinary Share Price (USD) | B14: =B13/B12 -> 22.515
A15: Market Capitalisation (USD m) | B15: =B11*B14 -> 49983.3
A16: Net Debt (USD m) | B16: 21854 | C16: Source: Diageo FY25 Preliminary Results, 5 Aug 2025 (net debt at 30 Jun 2025: $21.9bn)
A18: Income Statement Base — FY2025 Actual (USD m)
A19: Revenue / Net Sales | B19: 20245 | C19: Source: Diageo FY25 Preliminary Results, 5 Aug 2025
A20: Reported Operating Margin (for reference) | B20: 0.214 | C20: Source: Diageo FY25 Prelim Results — reported operating profit $4,335m / revenue $20,245m
A21: Organic Operating Margin (for reference) | B21: 0.28 | C21: Source: Diageo FY25 Form 20-F — organic/underlying basis, excludes FX & portfolio effects
A22: Normalised EBIT Margin (model input) | B22: 0.23 | C22: ANALYST ASSUMPTION: blend between reported (21.4%) and organic (28.0%) margins, reflecting Accelerate cost-savings phasing in — flagged as the single largest driver of this valuation, stress-test in Sensitivity tab
A23: Effective Tax Rate | B23: 0.25 | C23: Source: Diageo H1 FY26 results — tax rate before exceptional items guided ~25% for FY26
A24: D&A (% of Revenue) | B24: 0.103 | C24: ESTIMATE: (adjusted EBITDA of ~$6,428m, implied by net debt $21,854m / 3.4x leverage ratio, less reported EBIT $4,335m) / revenue
A25: CapEx (% of Revenue) | B25: 0.076 | C25: Source: Diageo FY25 Prelim Results — capex $1,549m / revenue $20,245m
A26: Increase in Net Working Capital (% of Revenue) | B26: 0.005 | C26: ASSUMPTION (not separately sourced) — small placeholder typical of a stable consumer staples business; revisit if better data found
A28: Growth Assumptions
A29: Revenue Growth — Year 1 (FY26E) | B29: 0.025 | C29: Assumption, roughly in line with FY26 guidance (organic sales growth ~similar to FY25's 1.7%)
A30: Revenue Growth — Year 2 (FY27E) | B30: 0.025
A31: Revenue Growth — Year 3 (FY28E) | B31: 0.025
A32: Revenue Growth — Year 4 (FY29E) | B32: 0.02 | C32: Tapering toward terminal growth
A33: Revenue Growth — Year 5 (FY30E) | B33: 0.02
A34: Terminal Growth Rate | B34: 0.02 | C34: Assumption, in line with long-run global nominal GDP / inflation
A36: WACC Build-Up
A37: Risk-Free Rate (US 10Y Treasury) | B37: 0.048 | C37: Source: US Treasury market yield, 1 Sep 2026 (~4.79-4.81%)
A38: Equity Risk Premium | B38: 0.05 | C38: Standard market assumption (broadly in line with typical US equity risk premium estimates)
A39: Beta | B39: 0.65 | C39: ASSUMPTION: blended midpoint of two sourced estimates — stockanalysis.com's recent 5Y beta of 0.30 (unusually low) and an older ~0.76 estimate — used since the two disagree substantially; refresh via fetch_diageo_data.py and re-examine before relying on either alone
A40: Cost of Equity | B40: =B37+B39*B38 -> 0.0805
A41: Pre-Tax Cost of Debt | B41: 0.055 | C41: ESTIMATE based on Diageo's investment-grade credit rating and a typical spread over the 10Y UST — not a directly quoted market rate
A42: After-Tax Cost of Debt | B42: =B41*(1-B23) -> 0.04125
A43: Weight of Equity | B43: =B15/(B15+B16) -> 0.69578478
A44: Weight of Debt | B44: =B16/(B15+B16) -> 0.30421522
A45: WACC | B45: =B43*B40+B44*B42 -> 0.068559553
...

Sheet DCF
A1: Diageo plc — 5-Year Unlevered DCF Forecast (USD m)
B3: FY2025A | C3: FY2026E | D3: FY2027E | E3: FY2028E | F3: FY2029E | G3: FY2030E
A4: Revenue | B4: =Assumptions!B19 -> 20245 | C4: =B4*(1+Assumptions!$B$29) -> 20751.125 | D4: =C4*(1+Assumptions!$B$30) -> 21269.903 | E4: =D4*(1+Assumptions!$B$31) -> 21801.651 | F4: =E4*(1+Assumptions!$B$32) -> 22237.684 | G4: =F4*(1+Assumptions!$B$33) -> 22682.437
A5: EBIT (Normalised Margin) | C5: =C4*Assumptions!$B$22 -> 4772.7587 | D5: =D4*Assumptions!$B$22 -> 4892.0777 | E5: =E4*Assumptions!$B$22 -> 5014.3797 | F5: =F4*Assumptions!$B$22 -> 5114.6673 | G5: =G4*Assumptions!$B$22 -> 5216.9606
A6: Less: Tax on EBIT | C6: =-C5*Assumptions!$B$23 -> -1193.1897 | D6: =-D5*Assumptions!$B$23 -> -1223.0194 | E6: =-E5*Assumptions!$B$23 -> -1253.5949 | F6: =-F5*Assumptions!$B$23 -> -1278.6668 | G6: =-G5*Assumptions!$B$23 -> -1304.2402
A7: NOPAT | C7: =C5+C6 -> 3579.5691 | D7: =D5+D6 -> 3669.0583 | E7: =E5+E6 -> 3760.7847 | F7: =F5+F6 -> 3836.0004 | G7: =G5+G6 -> 3912.7205
A8: Add: D&A | C8: =C4*Assumptions!$B$24 -> 2137.3659 | D8: =D4*Assumptions!$B$24 -> 2190.8 | E8: =E4*Assumptions!$B$24 -> 2245.57 | F8: =F4*Assumptions!$B$24 -> 2290.4814 | G8: =G4*Assumptions!$B$24 -> 2336.2911
A9: Less: CapEx | C9: =-C4*Assumptions!$B$25 -> -1577.0855 | D9: =-D4*Assumptions!$B$25 -> -1616.5126 | E9: =-E4*Assumptions!$B$25 -> -1656.9255 | F9: =-F4*Assumptions!$B$25 -> -1690.064 | G9: =-G4*Assumptions!$B$25 -> -1723.8652
A10: Less: Increase in NWC | C10: =-C4*Assumptions!$B$26 -> -103.75562 | D10: =-D4*Assumptions!$B$26 -> -106.34952 | E10: =-E4*Assumptions!$B$26 -> -109.00825 | F10: =-F4*Assumptions!$B$26 -> -111.18842 | G10: =-G4*Assumptions!$B$26 -> -113.41219
A11: Unlevered Free Cash Flow | C11: =SUM(C7:C10) -> 4036.0938 | D11: =SUM(D7:D10) -> 4136.9962 | E11: =SUM(E7:E10) -> 4240.4211 | F11: =SUM(F7:F10) -> 4325.2295 | G11: =SUM(G7:G10) -> 4411.7341
A13: Discount Period | C13: 1 | D13: 2 | E13: 3 | F13: 4 | G13: 5
A14: Discount Factor | C14: =1/(1+Assumptions!$B$45)^C13 -> 0.93583928 | D14: =1/(1+Assumptions!$B$45)^D13 -> 0.87579515 | E14: =1/(1+Assumptions!$B$45)^E13 -> 0.8196035 | F14: =1/(1+Assumptions!$B$45)^F13 -> 0.76701715 | G14: =1/(1+Assumptions!$B$45)^G13 -> 0.71780478
A15: PV of FCF | C15: =C11*C14 -> 3777.1351 | D15: =D11*D14 -> 3623.1612 | E15: =E11*E14 -> 3475.464 | F15: =F11*F14 -> 3317.5252 | G15: =G11*G14 -> 3166.7638
A17: Terminal Value (Gordon Growth Method)
A18: Terminal Year FCF (Yr5 x (1+g)) | B18: =G11*(1+Assumptions!$B$34) -> 4499.9688
A19: Terminal Value at End of Yr5 | B19: =B18/(Assumptions!$B$45-Assumptions!$B$34) -> 92669.074
A20: PV of Terminal Value | B20: =B19*G14 -> 66518.304
A22: Valuation Bridge
A23: Sum of PV of FCF (Yr1-5) | B23: =SUM(C15:G15) -> 17360.049
A24: PV of Terminal Value | B24: =B20 -> 66518.304
A25: Enterprise Value | B25: =B23+B24 -> 83878.353
A26: Less: Net Debt | B26: =-Assumptions!B16 -> -21854
A27: Equity Value | B27: =B25+B26 -> 62024.353
A28: Shares Outstanding (m) | B28: =Assumptions!B11 -> 2220
A29: Implied Value per Share (USD) | B29: =B27/B28 -> 27.938898
A30: Current Ordinary Share Price (USD) | B30: =Assumptions!B14 -> 22.515
A31: Implied Upside / (Downside) | B31: =B29/B30-1 -> 0.24090152
A33: Sanity check: Year-1 model FCF vs. Diageo's own guidance of ~$3bn+ FCF p.a. from FY26 (Accelerate programme)
A34: Model FY2026E FCF (USD m): | B34: =C11 -> 4036.0938
A36: Cross-check: Wall Street 12-month consensus price targets for DEO (ADR) clustered ~$106-129 in Aug 2026 (sources: TD Cowen $110, stockanalysis.com $129, other desks ~$106) — implying ~$26.50-$32.25 per ordinary share equivalent, which brackets this model's $27.94 output.

Sheet Sensitivity
A1: Sensitivity: Implied Value per Share (USD) — WACC vs. Terminal Growth Rate
A3: WACC \ Terminal g | C3: =Assumptions!$B$34-0.005 -> 0.015 | D3: =Assumptions!$B$34-0.0025 -> 0.0175 | E3: =Assumptions!$B$34 -> 0.02 | F3: =Assumptions!$B$34+0.0025 -> 0.0225 | G3: =Assumptions!$B$34+0.005 -> 0.025
B4: =Assumptions!$B$45-0.01 -> 0.058559553 | C4: =(SUMPRODUCT(DCF!$C$11:$G$11,(1+$B4)^(-DCF!$C$13:$G$13))+(DCF!$G$11*(1+C$3))/($B4-C$3)/(1+$B4)^5-Assumptions!$B$16)/Assumptions!$B$11 -> 33.032222 | D4: =(SUMPRODUCT(DCF!$C$11:$G$11,(1+$B4)^(-DCF!$C$13:$G$13))+(DCF!$G$11*(1+D$3))/($B4-D$3)/(1+$B4)^5-Assumptions!$B$16)/Assumptions!$B$11 -> 35.244489 | E4: =(SUMPRODUCT(DCF!$C$11:$G$11,(1+$B4)^(-DCF!$C$13:$G$13))+(DCF!$G$11*(1+E$3))/($B4-E$3)/(1+$B4)^5-Assumptions!$B$16)/Assumptions!$B$11 -> 37.74362 | F4: =(SUMPRODUCT(DCF!$C$11:$G$11,(1+$B4)^(-DCF!$C$13:$G$13))+(DCF!$G$11*(1+F$3))/($B4-F$3)/(1+$B4)^5-Assumptions!$B$16)/Assumptions!$B$11 -> 40.589279 | G4: =(SUMPRODUCT(DCF!$C$11:$G$11,(1+$B4)^(-DCF!$C$13:$G$13))+(DCF!$G$11*(1+G$3))/($B4-G$3)/(1+$B4)^5-Assumptions!$B$16)/Assumptions!$B$11 -> 43.858909
B5: =Assumptions!$B$45-0.005 -> 0.063559553 | C5: =(SUMPRODUCT(DCF!$C$11:$G$11,(1+$B5)^(-DCF!$C$13:$G$13))+(DCF!$G$11*(1+C$3))/($B5-C$3)/(1+$B5)^5-Assumptions!$B$16)/Assumptions!$B$11 -> 28.607213 | D5: =(SUMPRODUCT(DCF!$C$11:$G$11,(1+$B5)^(-DCF!$C$13:$G$13))+(DCF!$G$11*(1+D$3))/($B5-D$3)/(1+$B5)^5-Assumptions!$B$16)/Assumptions!$B$11 -> 30.343233 | E5: =(SUMPRODUCT(DCF!$C$11:$G$11,(1+$B5)^(-DCF!$C$13:$G$13))+(DCF!$G$11*(1+E$3))/($B5-E$3)/(1+$B5)^5-Assumptions!$B$16)/Assumptions!$B$11 -> 32.278522 | F5: =(SUMPRODUCT(DCF!$C$11:$G$11,(1+$B5)^(-DCF!$C$13:$G$13))+(DCF!$G$11*(1+F$3))/($B5-F$3)/(1+$B5)^5-Assumptions!$B$16)/Assumptions!$B$11 -> 34.449481 | G5: =(SUMPRODUCT(DCF!$C$11:$G$11,(1+$B5)^(-DCF!$C$13:$G$13))+(DCF!$G$11*(1+G$3))/($B5-G$3)/(1+$B5)^5-Assumptions!$B$16)/Assumptions!$B$11 -> 36.901946
B6: =Assumptions!$B$45 -> 0.068559553 | C6: =(SUMPRODUCT(DCF!$C$11:$G$11,(1+$B6)^(-DCF!$C$13:$G$13))+(DCF!$G$11*(1+C$3))/($B6-C$3)/(1+$B6)^5-Assumptions!$B$16)/Assumptions!$B$11 -> 25.008546 | D6: =(SUMPRODUCT(DCF!$C$11:$G$11,(1+$B6)^(-DCF!$C$13:$G$13))+(DCF!$G$11*(1+D$3))/($B6-D$3)/(1+$B6)^5-Assumptions!$B$16)/Assumptions!$B$11 -> 26.401983 | E6: =(SUMPRODUCT(DCF!$C$11:$G$11,(1+$B6)^(-DCF!$C$13:$G$13))+(DCF!$G$11*(1+E$3))/($B6-E$3)/(1+$B6)^5-Assumptions!$B$16)/Assumptions!$B$11 -> 27.938898 | F6: =(SUMPRODUCT(DCF!$C$11:$G$11,(1+$B6)^(-DCF!$C$13:$G$13))+(DCF!$G$11*(1+F$3))/($B6-F$3)/(1+$B6)^5-Assumptions!$B$16)/Assumptions!$B$11 -> 29.642652 | G6: =(SUMPRODUCT(DCF!$C$11:$G$11,(1+$B6)^(-DCF!$C$13:$G$13))+(DCF!$G$11*(1+G$3))/($B6-G$3)/(1+$B6)^5-Assumptions!$B$16)/Assumptions!$B$11 -> 31.541973
B7: =Assumptions!$B$45+0.005 -> 0.073559553 | C7: =(SUMPRODUCT(DCF!$C$11:$G$11,(1+$B7)^(-DCF!$C$13:$G$13))+(DCF!$G$11*(1+C$3))/($B7-C$3)/(1+$B7)^5-Assumptions!$B$16)/Assumptions!$B$11 -> 22.02455 | D7: =(SUMPRODUCT(DCF!$C$11:$G$11,(1+$B7)^(-DCF!$C$13:$G$13))+(DCF!$G$11*(1+D$3))/($B7-D$3)/(1+$B7)^5-Assumptions!$B$16)/Assumptions!$B$11 -> 23.163867 | E7: =(SUMPRODUCT(DCF!$C$11:$G$11,(1+$B7)^(-DCF!$C$13:$G$13))+(DCF!$G$11*(1+E$3))/($B7-E$3)/(1+$B7)^5-Assumptions!$B$16)/Assumptions!$B$11 -> 24.409543 | F7: =(SUMPRODUCT(DCF!$C$11:$G$11,(1+$B7)^(-DCF!$C$13:$G$13))+(DCF!$G$11*(1+F$3))/($B7-F$3)/(1+$B7)^5-Assumptions!$B$16)/Assumptions!$B$11 -> 25.777202 | G7: =(SUMPRODUCT(DCF!$C$11:$G$11,(1+$B7)^(-DCF!$C$13:$G$13))+(DCF!$G$11*(1+G$3))/($B7-G$3)/(1+$B7)^5-Assumptions!$B$16)/Assumptions!$B$11 -> 27.285684
B8: =Assumptions!$B$45+0.01 -> 0.078559553 | C8: =(SUMPRODUCT(DCF!$C$11:$G$11,(1+$B8)^(-DCF!$C$13:$G$13))+(DCF!$G$11*(1+C$3))/($B8-C$3)/(1+$B8)^5-Assumptions!$B$16)/Assumptions!$B$11 -> 19.510161 | D8: =(SUMPRODUCT(DCF!$C$11:$G$11,(1+$B8)^(-DCF!$C$13:$G$13))+(DCF!$G$11*(1+D$3))/($B8-D$3)/(1+$B8)^5-Assumptions!$B$16)/Assumptions!$B$11 -> 20.456148 | E8: =(SUMPRODUCT(DCF!$C$11:$G$11,(1+$B8)^(-DCF!$C$13:$G$13))+(DCF!$G$11*(1+E$3))/($B8-E$3)/(1+$B8)^5-Assumptions!$B$16)/Assumptions!$B$11 -> 21.482907 | F8: =(SUMPRODUCT(DCF!$C$11:$G$11,(1+$B8)^(-DCF!$C$13:$G$13))+(DCF!$G$11*(1+F$3))/($B8-F$3)/(1+$B8)^5-Assumptions!$B$16)/Assumptions!$B$11 -> 22.601244 | G8: =(SUMPRODUCT(DCF!$C$11:$G$11,(1+$B8)^(-DCF!$C$13:$G$13))+(DCF!$G$11*(1+G$3))/($B8-G$3)/(1+$B8)^5-Assumptions!$B$16)/Assumptions!$B$11 -> 23.823981
A10: Base case (centre cell, E6) should match the Implied Value per Share on the DCF tab.
